2024-05-08 23:00:35,798 FILE: creds.py IN: create_new_token MESSAGE: Ошибка получения токена: HTTPConnectionPool(host='169.254.169.254', port=80): Max retries exceeded with url: /computeMetadata/v1/instance/service-accounts/default/token (Caused by ConnectTimeoutError(<urllib3.connection.HTTPConnection object at 0x0000024DB2324AF0>, 'Connection to 169.254.169.254 timed out. (connect timeout=None)'))
